[2025-10-12T15:20:55.386+0000] {local_task_job_runner.py:120} INFO - ::group::Pre task execution logs
[2025-10-12T15:20:55.415+0000] {taskinstance.py:2076} INFO - Dependencies all met for dep_context=non-requeueable deps ti=<TaskInstance: etl_mlflow.run_etl manual__2025-10-12T15:20:47.529775+00:00 [queued]>
[2025-10-12T15:20:55.427+0000] {taskinstance.py:2076} INFO - Dependencies all met for dep_context=requeueable deps ti=<TaskInstance: etl_mlflow.run_etl manual__2025-10-12T15:20:47.529775+00:00 [queued]>
[2025-10-12T15:20:55.428+0000] {taskinstance.py:2306} INFO - Starting attempt 1 of 2
[2025-10-12T15:20:55.443+0000] {taskinstance.py:2330} INFO - Executing <Task(_PythonDecoratedOperator): run_etl> on 2025-10-12 15:20:47.529775+00:00
[2025-10-12T15:20:55.459+0000] {standard_task_runner.py:90} INFO - Running: ['***', 'tasks', 'run', 'etl_mlflow', 'run_etl', 'manual__2025-10-12T15:20:47.529775+00:00', '--job-id', '22', '--raw', '--subdir', 'DAGS_FOLDER/etl_mlflow.py', '--cfg-path', '/tmp/tmp1rtyqob4']
[2025-10-12T15:20:55.459+0000] {warnings.py:112} WARNING - /home/***/.local/lib/python3.12/site-packages/***/task/task_runner/standard_task_runner.py:61: DeprecationWarning: This process (pid=176) is multi-threaded, use of fork() may lead to deadlocks in the child.
  pid = os.fork()

[2025-10-12T15:20:55.461+0000] {standard_task_runner.py:91} INFO - Job 22: Subtask run_etl
[2025-10-12T15:20:55.461+0000] {standard_task_runner.py:63} INFO - Started process 187 to run task
[2025-10-12T15:20:55.512+0000] {task_command.py:426} INFO - Running <TaskInstance: etl_mlflow.run_etl manual__2025-10-12T15:20:47.529775+00:00 [running]> on host 7920bc5e4faa
[2025-10-12T15:20:55.625+0000] {taskinstance.py:2648} INFO - Exporting env vars: AIRFLOW_CTX_DAG_OWNER='***' AIRFLOW_CTX_DAG_ID='etl_mlflow' AIRFLOW_CTX_TASK_ID='run_etl' AIRFLOW_CTX_EXECUTION_DATE='2025-10-12T15:20:47.529775+00:00' AIRFLOW_CTX_TRY_NUMBER='1' AIRFLOW_CTX_DAG_RUN_ID='manual__2025-10-12T15:20:47.529775+00:00'
[2025-10-12T15:20:55.628+0000] {taskinstance.py:430} INFO - ::endgroup::
[2025-10-12T15:20:55.686+0000] {connectionpool.py:874} WARNING - Retrying (Retry(total=6, connect=6, read=7, redirect=7, status=7)) after connection broken by 'NewConnectionError('<urllib3.connection.HTTPConnection object at 0x7fefb5b8f770>: Failed to establish a new connection: [Errno 111] Connection refused')': /api/2.0/mlflow/experiments/get-by-name?experiment_name=burn_rate_eda
[2025-10-12T15:21:00.155+0000] {connectionpool.py:874} WARNING - Retrying (Retry(total=5, connect=5, read=7, redirect=7, status=7)) after connection broken by 'NewConnectionError('<urllib3.connection.HTTPConnection object at 0x7fefb5b8e5d0>: Failed to establish a new connection: [Errno 111] Connection refused')': /api/2.0/mlflow/experiments/get-by-name?experiment_name=burn_rate_eda
[2025-10-12T15:21:08.197+0000] {connectionpool.py:874} WARNING - Retrying (Retry(total=4, connect=4, read=7, redirect=7, status=7)) after connection broken by 'NewConnectionError('<urllib3.connection.HTTPConnection object at 0x7fefea124770>: Failed to establish a new connection: [Errno 111] Connection refused')': /api/2.0/mlflow/experiments/get-by-name?experiment_name=burn_rate_eda
[2025-10-12T15:21:24.264+0000] {connectionpool.py:874} WARNING - Retrying (Retry(total=3, connect=3, read=7, redirect=7, status=7)) after connection broken by 'NewConnectionError('<urllib3.connection.HTTPConnection object at 0x7fefea124f80>: Failed to establish a new connection: [Errno 111] Connection refused')': /api/2.0/mlflow/experiments/get-by-name?experiment_name=burn_rate_eda
[2025-10-12T15:21:56.723+0000] {connectionpool.py:874} WARNING - Retrying (Retry(total=2, connect=2, read=7, redirect=7, status=7)) after connection broken by 'NewConnectionError('<urllib3.connection.HTTPConnection object at 0x7fefea125640>: Failed to establish a new connection: [Errno 111] Connection refused')': /api/2.0/mlflow/experiments/get-by-name?experiment_name=burn_rate_eda
[2025-10-12T15:23:01.294+0000] {connectionpool.py:874} WARNING - Retrying (Retry(total=1, connect=1, read=7, redirect=7, status=7)) after connection broken by 'NewConnectionError('<urllib3.connection.HTTPConnection object at 0x7fefea125670>: Failed to establish a new connection: [Errno 111] Connection refused')': /api/2.0/mlflow/experiments/get-by-name?experiment_name=burn_rate_eda
[2025-10-12T15:25:01.296+0000] {connectionpool.py:874} WARNING - Retrying (Retry(total=0, connect=0, read=7, redirect=7, status=7)) after connection broken by 'NewConnectionError('<urllib3.connection.HTTPConnection object at 0x7fefea125d30>: Failed to establish a new connection: [Errno 111] Connection refused')': /api/2.0/mlflow/experiments/get-by-name?experiment_name=burn_rate_eda
[2025-10-12T15:25:06.673+0000] {credentials.py:1147} INFO - Found credentials in environment variables.
[2025-10-12T15:25:07.005+0000] {logging_mixin.py:188} INFO - üèÉ View run EDA_Run at: http://mlflow:5000/#/experiments/1/runs/a2d90c1dfa9b4bdbb8018da9b28793f1
[2025-10-12T15:25:07.006+0000] {logging_mixin.py:188} INFO - üß™ View experiment at: http://mlflow:5000/#/experiments/1
[2025-10-12T15:25:07.069+0000] {python.py:237} INFO - Done. Returned value was: {'X_train': '/tmp/X_train.csv', 'X_test': '/tmp/X_test.csv', 'y_train': '/tmp/y_train.csv', 'y_test': '/tmp/y_test.csv'}
[2025-10-12T15:25:07.070+0000] {taskinstance.py:441} INFO - ::group::Post task execution logs
[2025-10-12T15:25:07.097+0000] {taskinstance.py:1206} INFO - Marking task as SUCCESS. dag_id=etl_mlflow, task_id=run_etl, run_id=manual__2025-10-12T15:20:47.529775+00:00, execution_date=20251012T152047, start_date=20251012T152055, end_date=20251012T152507
[2025-10-12T15:25:07.138+0000] {local_task_job_runner.py:240} INFO - Task exited with return code 0
[2025-10-12T15:25:07.160+0000] {taskinstance.py:3503} INFO - 1 downstream tasks scheduled from follow-on schedule check
[2025-10-12T15:25:07.162+0000] {local_task_job_runner.py:222} INFO - ::endgroup::
